Workbook

Sheet As-Is Process Map
A1: BKKB Monthly Welfare Grant: As-Is Service Process Map
A2: Built from BKKB_Monthly_Welfare_Grant_AsIs.bpmn. Orange rows are inferred, not steps in the source map. Red rows are the defect exception path. Blue rows recur monthly.
A4: Seq | B4: Step ID | C4: Source reference | D4: Phase | E4: Organisation | F4: Performer | G4: Activity | H4: Input | I4: Output | J4: Next step / hand-off | K4: Channel / medium | L4: Stated time (source) | M4: Min (h) | N4: Max (h) | O4: Min (working days) | P4: Max (working days) | Q4: Citizen visits (in person) | R4: Cost to citizen (BDT) | S4: Activity type | T4: Basis | U4: Observations
A5: 1 | B5: A1 | C5: Table step 1 (map 1) | D5: P0. Application and attestation | E5: Legal heir / applicant | F5: Applicant | G5: Register on portal, fill in and print online application | H5: Death or disability of employee; decision to claim | I5: Printed application form | J5: E0 (employer attestation) | K5: Online (sss.bkkb.gov.bd) | L5: Not stated | R5: Not stated | S5: Citizen action | T5: Source | U5: Applicant may be the employee in disability cases, not an heir.
A6: 2 | B6: E0 | C6: Document list items 1 to 9 and 11 | D6: P0. Application and attestation | E6: Employer's office | F6: Employer office | G6: Attest document copies, countersign UP certificates, sign and seal application form | H6: Printed form; 11 supporting documents | I6: Attested documents; signed and sealed form | J6: A2 (applicant) | K6: In person; paper | L6: Not stated | Q6: 1 | R6: Not stated | S6: Verification (attestation) | T6: Inferred | U6: 10 of 11 documents need office attestation or countersignature. At least one in-person visit by the applicant.
A7: 3 | B7: A2 | C7: Table step 2 (map 1) | D7: P0. Application and attestation | E7: Legal heir / applicant | F7: Applicant | G7: Upload signed form and scanned documents; final submit | H7: Attested documents; signed form | I7: Online submission | J7: E1 (employer forwards hard copy) | K7: Online | L7: Not stated | R7: Not stated | S7: Citizen action | T7: Source | U7: No flow from the portal into the BKKB back office is shown. BKKB processing starts from the hard copy (E1).
A8: 4 | B8: E1 | C8: Table step 3 (map 2) | D8: P0. Application and attestation | E8: Employer's office | F8: Employer office | G8: Forward hard copy application with documents to BKKB | H8: Attested hard copy file | I8: Hard copy file received at BKKB | J8: S4 (BKKB helpdesk) | K8: By hand or post | L8: Not stated | R8: Not stated | S8: Despatch | T8: Source | U8: Duplicates the online submission. Postal or courier transit time not stated.
A9: 5 | B9: S4 | C9: Table step 4 | D9: A. Intake and downward marking | E9: BKKB Head Office | F9: Helpdesk (information provider) | G9: Receive hard copy application | H9: Hard copy application | I9: Application received | J9: S5 (DG) | K9: Paper | L9: Immediate | M9: 0 | N9: 0 | O9: =M9/'Assumptions & Legend'!$B$3 -> 0 | P9: =N9/'Assumptions & Legend'!$B$3 -> 0 | S9: Receipt and routing | T9: Source
A10: 6 | B10: S5 | C10: Table step 5 | D10: A. Intake and downward marking | E10: BKKB Head Office | F10: Director General | G10: Mark application | H10: Received application | I10: Marked application | J10: S6 (PA to DG) | K10: Paper file | L10: 2-3 h | M10: 2 | N10: 3 | O10: =M10/'Assumptions & Legend'!$B$3 -> 0.25 | P10: =N10/'Assumptions & Legend'!$B$3 -> 0.375 | S10: Marking / routing | T10: Source | U10: No decision taken. First of five marking steps before the section opens a file.
A11: 7 | B11: S6 | C11: Table step 6 | D11: A. Intake and downward marking | E11: BKKB Head Office | F11: PA to DG | G11: Enter in register; route onward | H11: Marked application | I11: Register entry; application routed | J11: S7 (Director, Admin) | K11: Paper register | L11: 0.5-1 h | M11: 0.5 | N11: 1 | O11: =M11/'Assumptions & Legend'!$B$3 -> 0.0625 | P11: =N11/'Assumptions & Legend'!$B$3 -> 0.125 | S11: Record-keeping | T11: Source | U11: Step label says route to Additional DG, but the next step is Director (Admin). Confirm with BKKB.
A12: 8 | B12: S7 | C12: Table step 7 | D12: A. Intake and downward marking | E12: BKKB Head Office | F12: Director (Admin) | G12: Mark application | H12: Routed application | I12: Marked application | J12: S8 (DD, Admin) | K12: Paper file | L12: 3-4 h | M12: 3 | N12: 4 | O12: =M12/'Assumptions & Legend'!$B$3 -> 0.375 | P12: =N12/'Assumptions & Legend'!$B$3 -> 0.5 | S12: Marking / routing | T12: Source
A13: 9 | B13: S8 | C13: Table step 8 | D13: A. Intake and downward marking | E13: BKKB Head Office | F13: Deputy Director (Admin) | G13: Mark application | H13: Marked application | I13: Marked application | J13: S9 (AD, Welfare) | K13: Paper file | L13: 3-4 h | M13: 3 | N13: 4 | O13: =M13/'Assumptions & Legend'!$B$3 -> 0.375 | P13: =N13/'Assumptions & Legend'!$B$3 -> 0.5 | S13: Marking / routing | T13: Source
A14: 10 | B14: S9 | C14: Table step 9 | D14: A. Intake and downward marking | E14: BKKB Head Office | F14: Assistant Director (Welfare) | G14: Mark application; send to section | H14: Marked application | I14: Application in Welfare section | J14: S10 (UDA) | K14: Paper file | L14: 3-4 h | M14: 3 | N14: 4 | O14: =M14/'Assumptions & Legend'!$B$3 -> 0.375 | P14: =N14/'Assumptions & Legend'!$B$3 -> 0.5 | S14: Marking / routing | T14: Source
A15: 11 | B15: S10 | C15: Table step 10 | D15: B. Section processing and document check | E15: BKKB Head Office | F15: Office Assistant / UDA | G15: Check index, open file, enter in file register, put up | H15: Application in section | I15: Case file opened and registered | J15: S11 (UDA) | K15: Paper file and register | L15: 1 day | M15: =1*'Assumptions & Legend'!$B$3 -> 8 | N15: =1*'Assumptions & Legend'!$B$3 -> 8 | O15: =M15/'Assumptions & Legend'!$B$3 -> 1 | P15: =N15/'Assumptions & Legend'!$B$3 -> 1 | S15: Record-keeping | T15: Source
A16: 12 | B16: S11 | C16: Table step 11 | D16: B. Section processing and document check | E16: BKKB Head Office | F16: Office Assistant / UDA | G16: Check documents received with application | H16: Case file | I16: Document check result | J16: G1 (decision) | K16: Paper file | L16: 1 day | M16: =1*'Assumptions & Legend'!$B$3 -> 8 | N16: =1*'Assumptions & Legend'!$B$3 -> 8 | O16: =M16/'Assumptions & Legend'!$B$3 -> 1 | P16: =N16/'Assumptions & Legend'!$B$3 -> 1 | S16: Verification | T16: Source | U16: The only substantive document check in the BKKB process.
A17: 13 | B17: G1 | C17: Source map decision | D17: B. Section processing and document check | E17: BKKB Head Office | F17: Office Assistant / UDA | G17: Decision: documents complete? | H17: Document check result | I17: Yes: S13. No: S12 | J17: S13 or S12 | K17: Paper file | L17: Not stated | S17: Decision | T17: Source | U17: Completeness check only. No eligibility determination and no rejection path documented.
A18: 14 | B18: S12 | C18: Table step 12 | D18: R. Defect return and rework (exception) | E18: BKKB Head Office | F18: Office Assistant / UDA | G18: Send SMS to applicant and letter to employer office listing defects | H18: Incomplete file | I18: SMS to applicant; letter to employer | J18: A3 and E_fix (rework); BKKB case closes | K18: SMS; paper letter | L18: Immediate | M18: 0 | N18: 0 | O18: =M18/'Assumptions & Legend'!$B$3 -> 0 | P18: =N18/'Assumptions & Legend'!$B$3 -> 0 | S18: Exception notification | T18: Source | U18: Resubmission arrives as a new hard copy and re-enters at S4, repeating the marking cascade.
A19: 15 | B19: A3 | C19: Map rework loop (to step 2) | D19: R. Defect return and rework (exception) | E19: Legal heir / applicant | F19: Applicant | G19: Correct defects in form or documents; re-upload | H19: Defect SMS | I19: Corrected online submission | J19: A2 (re-submit) | K19: Online | L19: Not stated | R19: Not stated | S19: Citizen action (rework) | T19: Inferred | U19: No time limit or rework cap.
A20: 16 | B20: E_fix | C20: Table step 12; map loop to step 2 | D20: R. Defect return and rework (exception) | E20: Employer's office | F20: Employer office | G20: Inform applicant; obtain corrected documents; re-attest and re-forward | H20: Defect letter | I20: Corrected hard copy file | J20: E1 (re-forward) | K20: In person; paper | L20: Not stated | Q20: 1 | R20: Not stated | S20: Rework | T20: Source | U20: Runs in parallel with A3. Two rework loops for one defect.
A21: 17 | B21: S13 | C21: Table step 13 | D21: C. Upward approval chain | E21: BKKB Head Office | F21: AD (Welfare) / Welfare Officer | G21: Approve; put up to Deputy Director | H21: Complete case file | I21: Approval note; file put up | J21: S14 (DD) | K21: Paper file | L21: Not stated | S21: Approval | T21: Source | U21: Time not stated in source.
A22: 18 | B22: S14 | C22: Table step 14 | D22: C. Upward approval chain | E22: BKKB Head Office | F22: Deputy Director (Admin) | G22: Check and approve | H22: File with approval note | I22: Approval | J22: S15 (Director) | K22: Paper file | L22: 2-3 h | M22: 2 | N22: 3 | O22: =M22/'Assumptions & Legend'!$B$3 -> 0.25 | P22: =N22/'Assumptions & Legend'!$B$3 -> 0.375 | S22: Approval | T22: Source | U22: No return or rejection outcome documented.
A23: 19 | B23: S15 | C23: Table step 15 | D23: C. Upward approval chain | E23: BKKB Head Office | F23: Director (Admin) | G23: Check file and draft order | H23: File | I23: Draft order approved | J23: S16 (ADG) | K23: Paper file | L23: 2-3 h | M23: 2 | N23: 3 | O23: =M23/'Assumptions & Legend'!$B$3 -> 0.25 | P23: =N23/'Assumptions & Legend'!$B$3 -> 0.375 | S23: Approval | T23: Source
A24: 20 | B24: S16 | C24: Table step 16 | D24: C. Upward approval chain | E24: BKKB Head Office | F24: Additional DG | G24: Approve; put up to DG | H24: File and draft order | I24: Approval | J24: S17 (DG) | K24: Paper file | L24: 2-3 h | M24: 2 | N24: 3 | O24: =M24/'Assumptions & Legend'!$B$3 -> 0.25 | P24: =N24/'Assumptions & Legend'!$B$3 -> 0.375 | S24: Approval | T24: Source | U24: Source map omits this step. Confirm with BKKB.
A25: 21 | B25: S17 | C25: Table step 17 | D25: C. Upward approval chain | E25: BKKB Head Office | F25: Director General | G25: Final approval; file goes down | H25: File and draft order | I25: Approved order | J25: S18 (Director) | K25: Paper file | L25: 2-3 h | M25: 2 | N25: 3 | O25: =M25/'Assumptions & Legend'!$B$3 -> 0.25 | P25: =N25/'Assumptions & Legend'!$B$3 -> 0.375 | S25: Approval | T25: Source | U25: Table names DG as final approver; map shows ADG. Confirm with BKKB.
A26: 22 | B26: S18 | C26: Table step 18 | D26: D. File returned down | E26: BKKB Head Office | F26: Director (Admin) | G26: Send file down | H26: Approved file | I26: File routed down | J26: S19 (DD) | K26: Paper file | L26: 0.5-1 h | M26: 0.5 | N26: 1 | O26: =M26/'Assumptions & Legend'!$B$3 -> 0.0625 | P26: =N26/'Assumptions & Legend'!$B$3 -> 0.125 | S26: Marking / routing | T26: Source
A27: 23 | B27: S19 | C27: Table step 19 | D27: D. File returned down | E27: BKKB Head Office | F27: Deputy Director (Admin) | G27: Send file down | H27: Approved file | I27: File routed down | J27: S20 (AD) | K27: Paper file | L27: 0.5-1 h | M27: 0.5 | N27: 1 | O27: =M27/'Assumptions & Legend'!$B$3 -> 0.0625 | P27: =N27/'Assumptions & Legend'!$B$3 -> 0.125 | S27: Marking / routing | T27: Source
A28: 24 | B28: S20 | C28: Table step 20 | D28: D. File returned down | E28: BKKB Head Office | F28: Assistant Director (Welfare) | G28: Receive file in section | H28: Approved file | I28: File in section | J28: S21 (Welfare Officer) | K28: Paper file | L28: 2-3 h | M28: 2 | N28: 3 | O28: =M28/'Assumptions & Legend'!$B$3 -> 0.25 | P28: =N28/'Assumptions & Legend'!$B$3 -> 0.375 | S28: Marking / routing | T28: Source
A29: 25 | B29: S21 | C29: Table step 21 | D29: E. Card printing and registration | E29: BKKB Head Office | F29: Welfare Officer | G29: Print approved order as three colour cards; send to UDA | H29: Approved order | I29: Three cards (applicant, bank and office copies) | J29: S22 (UDA) | K29: Paper cards | L29: 1 day | M29: =1*'Assumptions & Legend'!$B$3 -> 8 | N29: =1*'Assumptions & Legend'!$B$3 -> 8 | O29: =M29/'Assumptions & Legend'!$B$3 -> 1 | P29: =N29/'Assumptions & Legend'!$B$3 -> 1 | S29: Document production | T29: Source | U29: Paper card is the payment instrument.
A30: 26 | B30: S22 | C30: Table step 22 | D30: E. Card printing and registration | E30: BKKB Head Office | F30: Office Assistant / UDA | G30: Enter card numbers in register; send to Accounts Officer | H30: Printed cards | I30: Card register entry | J30: S23 (Accounts Officer) | K30: Paper register | L30: 4-5 h | M30: 4 | N30: 5 | O30: =M30/'Assumptions & Legend'!$B$3 -> 0.5 | P30: =N30/'Assumptions & Legend'!$B$3 -> 0.625 | S30: Record-keeping | T30: Source
A31: 27 | B31: S23 | C31: Table step 23 | D31: E. Card printing and registration | E31: BKKB Head Office | F31: Accounts Officer (Welfare) | G31: Sign card register | H31: Card register | I31: Signed register | J31: S24 (UDA) | K31: Paper register | L31: 0.5-1 h | M31: 0.5 | N31: 1 | O31: =M31/'Assumptions & Legend'!$B$3 -> 0.0625 | P31: =N31/'Assumptions & Legend'!$B$3 -> 0.125 | S31: Signature | T31: Source
A32: 28 | B32: S24 | C32: Table step 24 | D32: F. Card despatch to beneficiary | E32: BKKB Head Office | F32: Office Assistant / UDA | G32: Prepare forwarding letter for applicant card | H32: Applicant copy of card | I32: Draft forwarding letter | J32: S25 (AD) | K32: Paper letter | L32: 1 day | M32: =1*'Assumptions & Legend'!$B$3 -> 8 | N32: =1*'Assumptions & Legend'!$B$3 -> 8 | O32: =M32/'Assumptions & Legend'!$B$3 -> 1 | P32: =N32/'Assumptions & Legend'!$B$3 -> 1 | S32: Document production | T32: Source | U32: Card path (S24 to S27) runs before the bank path (S28 to S33) although the two are independent.
A33: 29 | B33: S25 | C33: Table step 25 | D33: F. Card despatch to beneficiary | E33: BKKB Head Office | F33: Assistant Director (Welfare) | G33: Sign forwarding letter | H33: Draft letter | I33: Signed letter | J33: S26 (Despatch Rider) | K33: Paper letter | L33: 4-5 h | M33: 4 | N33: 5 | O33: =M33/'Assumptions & Legend'!$B$3 -> 0.5 | P33: =N33/'Assumptions & Legend'!$B$3 -> 0.625 | S33: Signature | T33: Source
A34: 30 | B34: S26 | C34: Table step 26 | D34: F. Card despatch to beneficiary | E34: BKKB Head Office | F34: Despatch Rider | G34: Post applicant card to employer office by registered mail | H34: Card and signed letter | I34: Card in registered post | J34: S27 (Office Assistant); E_hand (employer) | K34: Registered post | L34: 1 day | M34: =1*'Assumptions & Legend'!$B$3 -> 8 | N34: =1*'Assumptions & Legend'!$B$3 -> 8 | O34: =M34/'Assumptions & Legend'!$B$3 -> 1 | P34: =N34/'Assumptions & Legend'!$B$3 -> 1 | S34: Despatch | T34: Source | U34: Postal transit time to employer not stated.
A35: 31 | B35: S27 | C35: Table step 27 | D35: F. Card despatch to beneficiary | E35: BKKB Head Office | F35: Office Assistant / UDA | G35: File registry slip in case file | H35: Registry slip | I35: Updated case file | J35: S28 (UDA) | K35: Paper file | L35: 0.5-1 h | M35: 0.5 | N35: 1 | O35: =M35/'Assumptions & Legend'!$B$3 -> 0.0625 | P35: =N35/'Assumptions & Legend'!$B$3 -> 0.125 | S35: Record-keeping | T35: Source
A36: 32 | B36: E_hand | C36: Comparison table, section 3(2) | D36: F. Card despatch to beneficiary | E36: Employer's office | F36: Employer office | G36: Hand over card to beneficiary, collected in person | H36: Card received by post | I36: Card with beneficiary | J36: A_pay (applicant) | K36: In person | L36: Not stated | Q36: 1 | R36: Not stated | S36: Hand-over | T36: Source | U36: Additional in-person visit by the beneficiary. Card may arrive before the branch holds its copy.
A37: 33 | B37: S28 | C37: Table step 28 | D37: G. Bank instruction | E37: BKKB Head Office | F37: Office Assistant / UDA | G37: Prepare card list and letter to Sonali Bank, Ramna | H37: Bank copies of cards | I37: Draft list and letter | J37: S29 (AD) | K37: Paper list and letter | L37: 1 day | M37: =1*'Assumptions & Legend'!$B$3 -> 8 | N37: =1*'Assumptions & Legend'!$B$3 -> 8 | O37: =M37/'Assumptions & Legend'!$B$3 -> 1 | P37: =N37/'Assumptions & Legend'!$B$3 -> 1 | S37: Document production | T37: Source | U37: Starts only after the card path completes.
A38: 34 | B38: S29 | C38: Table step 29 | D38: G. Bank instruction | E38: BKKB Head Office | F38: Assistant Director (Welfare) | G38: Sign file | H38: Draft list and letter | I38: Signed file | J38: S30 (DD) | K38: Paper file | L38: 5-6 h | M38: 5 | N38: 6 | O38: =M38/'Assumptions & Legend'!$B$3 -> 0.625 | P38: =N38/'Assumptions & Legend'!$B$3 -> 0.75 | S38: Signature | T38: Source
A39: 35 | B39: S30 | C39: Table step 30 | D39: G. Bank instruction | E39: BKKB Head Office | F39: Deputy Director (Admin) | G39: Sign list and letter | H39: Signed file | I39: Signed list and letter | J39: S31 (AD) | K39: Paper | L39: 2-3 h | M39: 2 | N39: 3 | O39: =M39/'Assumptions & Legend'!$B$3 -> 0.25 | P39: =N39/'Assumptions & Legend'!$B$3 -> 0.375 | S39: Signature | T39: Source
A40: 36 | B40: S31 | C40: Table step 31 | D40: G. Bank instruction | E40: BKKB Head Office | F40: Assistant Director (Welfare) | G40: Sign file; file goes down | H40: Signed list and letter | I40: File signed again | J40: S32 (Office Assistant) | K40: Paper file | L40: 0.5-1 h | M40: 0.5 | N40: 1 | O40: =M40/'Assumptions & Legend'!$B$3 -> 0.0625 | P40: =N40/'Assumptions & Legend'!$B$3 -> 0.125 | S40: Signature | T40: Source | U40: AD signs twice, either side of the DD signature at S30.
A41: 37 | B41: S32 | C41: Table step 32 | D41: G. Bank instruction | E41: BKKB Head Office | F41: Office Assistant / UDA | G41: Issue letter | H41: Signed list and letter | I41: Issued letter | J41: S33 (Despatch Rider) | K41: Paper letter | L41: 3-4 h | M41: 3 | N41: 4 | O41: =M41/'Assumptions & Legend'!$B$3 -> 0.375 | P41: =N41/'Assumptions & Legend'!$B$3 -> 0.5 | S41: Document production | T41: Source
...

Sheet Summary
A1: Summary of stated times, effort and structure
A2: All figures calculate from the 'As-Is Process Map' sheet. Working day = hours set on the Assumptions sheet.
A4: 1. Stated time by phase
A5: Phase | B5: Steps | C5: Steps with no stated time | D5: Min (h) | E5: Max (h) | F5: Min (working days) | G5: Max (working days)
A6: P0. Application and attestation | B6: =COUNTIF('As-Is Process Map'!$D$5:$D$46,A6) -> 4 | C6: =COUNTIFS('As-Is Process Map'!$D$5:$D$46,A6,'As-Is Process Map'!$L$5:$L$46,"Not stated") -> 4 | D6: =SUMIFS('As-Is Process Map'!$M$5:$M$46,'As-Is Process Map'!$D$5:$D$46,A6) -> 0 | E6: =SUMIFS('As-Is Process Map'!$N$5:$N$46,'As-Is Process Map'!$D$5:$D$46,A6) -> 0 | F6: =D6/'Assumptions & Legend'!$B$3 -> 0 | G6: =E6/'Assumptions & Legend'!$B$3 -> 0
A7: A. Intake and downward marking | B7: =COUNTIF('As-Is Process Map'!$D$5:$D$46,A7) -> 6 | C7: =COUNTIFS('As-Is Process Map'!$D$5:$D$46,A7,'As-Is Process Map'!$L$5:$L$46,"Not stated") -> 0 | D7: =SUMIFS('As-Is Process Map'!$M$5:$M$46,'As-Is Process Map'!$D$5:$D$46,A7) -> 11.5 | E7: =SUMIFS('As-Is Process Map'!$N$5:$N$46,'As-Is Process Map'!$D$5:$D$46,A7) -> 16 | F7: =D7/'Assumptions & Legend'!$B$3 -> 1.4375 | G7: =E7/'Assumptions & Legend'!$B$3 -> 2
A8: B. Section processing and document check | B8: =COUNTIF('As-Is Process Map'!$D$5:$D$46,A8) -> 3 | C8: =COUNTIFS('As-Is Process Map'!$D$5:$D$46,A8,'As-Is Process Map'!$L$5:$L$46,"Not stated") -> 1 | D8: =SUMIFS('As-Is Process Map'!$M$5:$M$46,'As-Is Process Map'!$D$5:$D$46,A8) -> 16 | E8: =SUMIFS('As-Is Process Map'!$N$5:$N$46,'As-Is Process Map'!$D$5:$D$46,A8) -> 16 | F8: =D8/'Assumptions & Legend'!$B$3 -> 2 | G8: =E8/'Assumptions & Legend'!$B$3 -> 2
A9: R. Defect return and rework (exception) | B9: =COUNTIF('As-Is Process Map'!$D$5:$D$46,A9) -> 3 | C9: =COUNTIFS('As-Is Process Map'!$D$5:$D$46,A9,'As-Is Process Map'!$L$5:$L$46,"Not stated") -> 2 | D9: =SUMIFS('As-Is Process Map'!$M$5:$M$46,'As-Is Process Map'!$D$5:$D$46,A9) -> 0 | E9: =SUMIFS('As-Is Process Map'!$N$5:$N$46,'As-Is Process Map'!$D$5:$D$46,A9) -> 0 | F9: =D9/'Assumptions & Legend'!$B$3 -> 0 | G9: =E9/'Assumptions & Legend'!$B$3 -> 0
A10: C. Upward approval chain | B10: =COUNTIF('As-Is Process Map'!$D$5:$D$46,A10) -> 5 | C10: =COUNTIFS('As-Is Process Map'!$D$5:$D$46,A10,'As-Is Process Map'!$L$5:$L$46,"Not stated") -> 1 | D10: =SUMIFS('As-Is Process Map'!$M$5:$M$46,'As-Is Process Map'!$D$5:$D$46,A10) -> 8 | E10: =SUMIFS('As-Is Process Map'!$N$5:$N$46,'As-Is Process Map'!$D$5:$D$46,A10) -> 12 | F10: =D10/'Assumptions & Legend'!$B$3 -> 1 | G10: =E10/'Assumptions & Legend'!$B$3 -> 1.5
A11: D. File returned down | B11: =COUNTIF('As-Is Process Map'!$D$5:$D$46,A11) -> 3 | C11: =COUNTIFS('As-Is Process Map'!$D$5:$D$46,A11,'As-Is Process Map'!$L$5:$L$46,"Not stated") -> 0 | D11: =SUMIFS('As-Is Process Map'!$M$5:$M$46,'As-Is Process Map'!$D$5:$D$46,A11) -> 3 | E11: =SUMIFS('As-Is Process Map'!$N$5:$N$46,'As-Is Process Map'!$D$5:$D$46,A11) -> 5 | F11: =D11/'Assumptions & Legend'!$B$3 -> 0.375 | G11: =E11/'Assumptions & Legend'!$B$3 -> 0.625
A12: E. Card printing and registration | B12: =COUNTIF('As-Is Process Map'!$D$5:$D$46,A12) -> 3 | C12: =COUNTIFS('As-Is Process Map'!$D$5:$D$46,A12,'As-Is Process Map'!$L$5:$L$46,"Not stated") -> 0 | D12: =SUMIFS('As-Is Process Map'!$M$5:$M$46,'As-Is Process Map'!$D$5:$D$46,A12) -> 12.5 | E12: =SUMIFS('As-Is Process Map'!$N$5:$N$46,'As-Is Process Map'!$D$5:$D$46,A12) -> 14 | F12: =D12/'Assumptions & Legend'!$B$3 -> 1.5625 | G12: =E12/'Assumptions & Legend'!$B$3 -> 1.75
A13: F. Card despatch to beneficiary | B13: =COUNTIF('As-Is Process Map'!$D$5:$D$46,A13) -> 5 | C13: =COUNTIFS('As-Is Process Map'!$D$5:$D$46,A13,'As-Is Process Map'!$L$5:$L$46,"Not stated") -> 1 | D13: =SUMIFS('As-Is Process Map'!$M$5:$M$46,'As-Is Process Map'!$D$5:$D$46,A13) -> 20.5 | E13: =SUMIFS('As-Is Process Map'!$N$5:$N$46,'As-Is Process Map'!$D$5:$D$46,A13) -> 22 | F13: =D13/'Assumptions & Legend'!$B$3 -> 2.5625 | G13: =E13/'Assumptions & Legend'!$B$3 -> 2.75
A14: G. Bank instruction | B14: =COUNTIF('As-Is Process Map'!$D$5:$D$46,A14) -> 6 | C14: =COUNTIFS('As-Is Process Map'!$D$5:$D$46,A14,'As-Is Process Map'!$L$5:$L$46,"Not stated") -> 0 | D14: =SUMIFS('As-Is Process Map'!$M$5:$M$46,'As-Is Process Map'!$D$5:$D$46,A14) -> 26.5 | E14: =SUMIFS('As-Is Process Map'!$N$5:$N$46,'As-Is Process Map'!$D$5:$D$46,A14) -> 30 | F14: =D14/'Assumptions & Legend'!$B$3 -> 3.3125 | G14: =E14/'Assumptions & Legend'!$B$3 -> 3.75
A15: H. Bank distribution | B15: =COUNTIF('As-Is Process Map'!$D$5:$D$46,A15) -> 2 | C15: =COUNTIFS('As-Is Process Map'!$D$5:$D$46,A15,'As-Is Process Map'!$L$5:$L$46,"Not stated") -> 1 | D15: =SUMIFS('As-Is Process Map'!$M$5:$M$46,'As-Is Process Map'!$D$5:$D$46,A15) -> 56 | E15: =SUMIFS('As-Is Process Map'!$N$5:$N$46,'As-Is Process Map'!$D$5:$D$46,A15) -> 56 | F15: =D15/'Assumptions & Legend'!$B$3 -> 7 | G15: =E15/'Assumptions & Legend'!$B$3 -> 7
A16: I. Monthly disbursement (recurring) | B16: =COUNTIF('As-Is Process Map'!$D$5:$D$46,A16) -> 2 | C16: =COUNTIFS('As-Is Process Map'!$D$5:$D$46,A16,'As-Is Process Map'!$L$5:$L$46,"Not stated") -> 2 | D16: =SUMIFS('As-Is Process Map'!$M$5:$M$46,'As-Is Process Map'!$D$5:$D$46,A16) -> 0 | E16: =SUMIFS('As-Is Process Map'!$N$5:$N$46,'As-Is Process Map'!$D$5:$D$46,A16) -> 0 | F16: =D16/'Assumptions & Legend'!$B$3 -> 0 | G16: =E16/'Assumptions & Legend'!$B$3 -> 0
A17: BKKB pre-decision (A to C) | B17: =B7+B8+B10 -> 14 | C17: =C7+C8+C10 -> 2 | D17: =D7+D8+D10 -> 35.5 | E17: =E7+E8+E10 -> 44 | F17: =D17/'Assumptions & Legend'!$B$3 -> 4.4375 | G17: =E17/'Assumptions & Legend'!$B$3 -> 5.5
A18: BKKB post-decision (D to G) | B18: =B11+B12+B13+B14 -> 17 | C18: =C11+C12+C13+C14 -> 1 | D18: =D11+D12+D13+D14 -> 62.5 | E18: =E11+E12+E13+E14 -> 71 | F18: =D18/'Assumptions & Legend'!$B$3 -> 7.8125 | G18: =E18/'Assumptions & Legend'!$B$3 -> 8.875
A19: BKKB total (A to G) | B19: =B7+B8+B10+B11+B12+B13+B14 -> 31 | C19: =C7+C8+C10+C11+C12+C13+C14 -> 3 | D19: =D7+D8+D10+D11+D12+D13+D14 -> 98 | E19: =E7+E8+E10+E11+E12+E13+E14 -> 115 | F19: =D19/'Assumptions & Legend'!$B$3 -> 12.25 | G19: =E19/'Assumptions & Legend'!$B$3 -> 14.375
A20: Stated total, BKKB receipt to cards at branches (A to H) | B20: =B7+B8+B10+B11+B12+B13+B14+B15 -> 33 | C20: =C7+C8+C10+C11+C12+C13+C14+C15 -> 4 | D20: =D7+D8+D10+D11+D12+D13+D14+D15 -> 154 | E20: =E7+E8+E10+E11+E12+E13+E14+E15 -> 171 | F20: =D20/'Assumptions & Legend'!$B$3 -> 19.25 | G20: =E20/'Assumptions & Legend'!$B$3 -> 21.375 | H20: Excludes P0, rework (R), monthly disbursement (I), postal transit and S13.
A21: Post-decision share of BKKB time (min / max) | D21: =D18/D19 -> 0.6377551 | E21: =E18/E19 -> 0.6173913
A22: Critical-path saving if card path (F) runs in parallel with bank path (G) | D22: =D13 -> 20.5 | E22: =E13 -> 22 | F22: =D22/'Assumptions & Legend'!$B$3 -> 2.5625 | G22: =E22/'Assumptions & Legend'!$B$3 -> 2.75 | H22: Valid because G is longer than F, so F leaves the critical path.
A24: 2. Workload by performer
A25: Performer | B25: Organisation | C25: Steps | D25: Min (h) | E25: Max (h) | F25: Min (working days) | G25: Max (working days)
A26: Applicant | B26: Legal heir / applicant | C26: =COUNTIF('As-Is Process Map'!$F$5:$F$46,A26) -> 3 | D26: =SUMIFS('As-Is Process Map'!$M$5:$M$46,'As-Is Process Map'!$F$5:$F$46,A26) -> 0 | E26: =SUMIFS('As-Is Process Map'!$N$5:$N$46,'As-Is Process Map'!$F$5:$F$46,A26) -> 0 | F26: =D26/'Assumptions & Legend'!$B$3 -> 0 | G26: =E26/'Assumptions & Legend'!$B$3 -> 0
A27: Employer office | B27: Employer's office | C27: =COUNTIF('As-Is Process Map'!$F$5:$F$46,A27) -> 4 | D27: =SUMIFS('As-Is Process Map'!$M$5:$M$46,'As-Is Process Map'!$F$5:$F$46,A27) -> 0 | E27: =SUMIFS('As-Is Process Map'!$N$5:$N$46,'As-Is Process Map'!$F$5:$F$46,A27) -> 0 | F27: =D27/'Assumptions & Legend'!$B$3 -> 0 | G27: =E27/'Assumptions & Legend'!$B$3 -> 0
A28: Helpdesk (information provider) | B28: BKKB Head Office | C28: =COUNTIF('As-Is Process Map'!$F$5:$F$46,A28) -> 1 | D28: =SUMIFS('As-Is Process Map'!$M$5:$M$46,'As-Is Process Map'!$F$5:$F$46,A28) -> 0 | E28: =SUMIFS('As-Is Process Map'!$N$5:$N$46,'As-Is Process Map'!$F$5:$F$46,A28) -> 0 | F28: =D28/'Assumptions & Legend'!$B$3 -> 0 | G28: =E28/'Assumptions & Legend'!$B$3 -> 0
A29: Director General | B29: BKKB Head Office | C29: =COUNTIF('As-Is Process Map'!$F$5:$F$46,A29) -> 2 | D29: =SUMIFS('As-Is Process Map'!$M$5:$M$46,'As-Is Process Map'!$F$5:$F$46,A29) -> 4 | E29: =SUMIFS('As-Is Process Map'!$N$5:$N$46,'As-Is Process Map'!$F$5:$F$46,A29) -> 6 | F29: =D29/'Assumptions & Legend'!$B$3 -> 0.5 | G29: =E29/'Assumptions & Legend'!$B$3 -> 0.75
A30: PA to DG | B30: BKKB Head Office | C30: =COUNTIF('As-Is Process Map'!$F$5:$F$46,A30) -> 1 | D30: =SUMIFS('As-Is Process Map'!$M$5:$M$46,'As-Is Process Map'!$F$5:$F$46,A30) -> 0.5 | E30: =SUMIFS('As-Is Process Map'!$N$5:$N$46,'As-Is Process Map'!$F$5:$F$46,A30) -> 1 | F30: =D30/'Assumptions & Legend'!$B$3 -> 0.0625 | G30: =E30/'Assumptions & Legend'!$B$3 -> 0.125
A31: Director (Admin) | B31: BKKB Head Office | C31: =COUNTIF('As-Is Process Map'!$F$5:$F$46,A31) -> 3 | D31: =SUMIFS('As-Is Process Map'!$M$5:$M$46,'As-Is Process Map'!$F$5:$F$46,A31) -> 5.5 | E31: =SUMIFS('As-Is Process Map'!$N$5:$N$46,'As-Is Process Map'!$F$5:$F$46,A31) -> 8 | F31: =D31/'Assumptions & Legend'!$B$3 -> 0.6875 | G31: =E31/'Assumptions & Legend'!$B$3 -> 1
A32: Deputy Director (Admin) | B32: BKKB Head Office | C32: =COUNTIF('As-Is Process Map'!$F$5:$F$46,A32) -> 4 | D32: =SUMIFS('As-Is Process Map'!$M$5:$M$46,'As-Is Process Map'!$F$5:$F$46,A32) -> 7.5 | E32: =SUMIFS('As-Is Process Map'!$N$5:$N$46,'As-Is Process Map'!$F$5:$F$46,A32) -> 11 | F32: =D32/'Assumptions & Legend'!$B$3 -> 0.9375 | G32: =E32/'Assumptions & Legend'!$B$3 -> 1.375
A33: Assistant Director (Welfare) | B33: BKKB Head Office | C33: =COUNTIF('As-Is Process Map'!$F$5:$F$46,A33) -> 5 | D33: =SUMIFS('As-Is Process Map'!$M$5:$M$46,'As-Is Process Map'!$F$5:$F$46,A33) -> 14.5 | E33: =SUMIFS('As-Is Process Map'!$N$5:$N$46,'As-Is Process Map'!$F$5:$F$46,A33) -> 19 | F33: =D33/'Assumptions & Legend'!$B$3 -> 1.8125 | G33: =E33/'Assumptions & Legend'!$B$3 -> 2.375
A34: Office Assistant / UDA | B34: BKKB Head Office | C34: =COUNTIF('As-Is Process Map'!$F$5:$F$46,A34) -> 9 | D34: =SUMIFS('As-Is Process Map'!$M$5:$M$46,'As-Is Process Map'!$F$5:$F$46,A34) -> 39.5 | E34: =SUMIFS('As-Is Process Map'!$N$5:$N$46,'As-Is Process Map'!$F$5:$F$46,A34) -> 42 | F34: =D34/'Assumptions & Legend'!$B$3 -> 4.9375 | G34: =E34/'Assumptions & Legend'!$B$3 -> 5.25
A35: AD (Welfare) / Welfare Officer | B35: BKKB Head Office | C35: =COUNTIF('As-Is Process Map'!$F$5:$F$46,A35) -> 1 | D35: =SUMIFS('As-Is Process Map'!$M$5:$M$46,'As-Is Process Map'!$F$5:$F$46,A35) -> 0 | E35: =SUMIFS('As-Is Process Map'!$N$5:$N$46,'As-Is Process Map'!$F$5:$F$46,A35) -> 0 | F35: =D35/'Assumptions & Legend'!$B$3 -> 0 | G35: =E35/'Assumptions & Legend'!$B$3 -> 0
A36: Additional DG | B36: BKKB Head Office | C36: =COUNTIF('As-Is Process Map'!$F$5:$F$46,A36) -> 1 | D36: =SUMIFS('As-Is Process Map'!$M$5:$M$46,'As-Is Process Map'!$F$5:$F$46,A36) -> 2 | E36: =SUMIFS('As-Is Process Map'!$N$5:$N$46,'As-Is Process Map'!$F$5:$F$46,A36) -> 3 | F36: =D36/'Assumptions & Legend'!$B$3 -> 0.25 | G36: =E36/'Assumptions & Legend'!$B$3 -> 0.375
A37: Welfare Officer | B37: BKKB Head Office | C37: =COUNTIF('As-Is Process Map'!$F$5:$F$46,A37) -> 1 | D37: =SUMIFS('As-Is Process Map'!$M$5:$M$46,'As-Is Process Map'!$F$5:$F$46,A37) -> 8 | E37: =SUMIFS('As-Is Process Map'!$N$5:$N$46,'As-Is Process Map'!$F$5:$F$46,A37) -> 8 | F37: =D37/'Assumptions & Legend'!$B$3 -> 1 | G37: =E37/'Assumptions & Legend'!$B$3 -> 1
... A42: Beneficiary | B42: Legal heir / applicant | C42: =COUNTIF('As-Is Process Map'!$F$5:$F$46,A42) -> 1 | D42: =SUMIFS('As-Is Process Map'!$M$5:$M$46,'As-Is Process Map'!$F$5:$F$46,A42) -> 0 | E42: =SUMIFS('As-Is Process Map'!$N$5:$N$46,'As-Is Process Map'!$F$5:$F$46,A42) -> 0 | F42: =D42/'Assumptions & Legend'!$B$3 -> 0 | G42: =E42/'Assumptions & Legend'!$B$3 -> 0
A44: 3. Steps by activity type
A45: Activity type | B45: All steps | C45: BKKB steps | D45: Min (h) | E45: Max (h)
A46: Citizen action | B46: =COUNTIF('As-Is Process Map'!$S$5:$S$46,A46) -> 2 | C46: =COUNTIFS('As-Is Process Map'!$S$5:$S$46,A46,'As-Is Process Map'!$E$5:$E$46,"BKKB Head Office") -> 0 | D46: =SUMIFS('As-Is Process Map'!$M$5:$M$46,'As-Is Process Map'!$S$5:$S$46,A46) -> 0 | E46: =SUMIFS('As-Is Process Map'!$N$5:$N$46,'As-Is Process Map'!$S$5:$S$46,A46) -> 0
A47: Verification (attestation) | B47: =COUNTIF('As-Is Process Map'!$S$5:$S$46,A47) -> 1 | C47: =COUNTIFS('As-Is Process Map'!$S$5:$S$46,A47,'As-Is Process Map'!$E$5:$E$46,"BKKB Head Office") -> 0 | D47: =SUMIFS('As-Is Process Map'!$M$5:$M$46,'As-Is Process Map'!$S$5:$S$46,A47) -> 0 | E47: =SUMIFS('As-Is Process Map'!$N$5:$N$46,'As-Is Process Map'!$S$5:$S$46,A47) -> 0
...

Sheet Issues & Gaps
A1: Open issues, model inconsistencies and measurement gaps
A3: ID | B3: Ref | C3: Category | D3: Issue | E3: Implication | F3: Confirm with
A4: I01 | B4: S6 | C4: Model inconsistency | D4: S6 label says route to Additional DG, but the next step is S7 Director (Admin). The ADG lane holds only S16. | E4: Either the label or the routing is wrong; affects marking-chain length. | F4: BKKB Admin
A5: I02 | B5: S16 / S17 | C5: Model inconsistency | D5: Step table names DG as final approver (S17); source map shows ADG (map step 15) and omits S16. | E5: Approval chain may be four or five levels. | F5: BKKB Admin
A6: I03 | B6: S13 to S17 | C6: Structural gap | D6: All five approvals are modelled as approve only. No return or rejection outcome documented. | E6: Either approvals add no independent check, or an undocumented exception path exists. | F6: BKKB Welfare section
A7: I04 | B7: G1 | C7: Structural gap | D7: Only a completeness check exists. No eligibility determination or ineligibility path is documented. | E7: Eligibility appears to be assumed from employer attestation. | F7: BKKB Welfare section
A8: I05 | B8: S12 / S4 | C8: Assumption | D8: Model assumes a corrected file re-enters at S4 and repeats the full marking cascade. | E8: Rework cost per cycle of at least 3.4 to 4 working days inside BKKB if confirmed. | F8: BKKB Welfare section
A9: I06 | B9: A2 / E1 | C9: Structural finding | D9: The online submission has no downstream consumer at BKKB; processing starts from the hard copy. | E9: Citizen submits twice, once online and once on paper through the employer. | F9: BKKB IT; Welfare section
A10: I07 | B10: A_pay / Br2 | C10: Model inconsistency | D10: Monthly cash withdrawal is modelled as a single occurrence. | E10: Understates the largest citizen burden (up to 180 visits). Add loop marker or recurring sub-process. | F10: Model owner
A11: I08 | B11: E_hand / Br1 | C11: Structural gap | D11: Beneficiary may receive the card before Ramna's 7-day distribution reaches the branch. | E11: Risk of a failed first branch visit; not shown in model. | F11: Sonali Bank
A12: I09 | B12: P0, S13, E_hand, Br1 | C12: Measurement gap | D12: No stated time for applicant and employer steps, S13, card hand-over or branch filing. | E12: True citizen-experienced duration cannot be quantified. | F12: BKKB; employer offices
A13: I10 | B13: All | C13: Measurement gap | D13: No end-to-end time (first action to first cash), rework rate or case volume in source. | E13: No baseline for To-Be targets. | F13: BKKB MIS / file registers
A14: I11 | B14: All T values | C14: Measurement gap | D14: Unclear whether stated times are touch time or elapsed time including queues. '1 day' entries suggest queue time. | E14: Totals may overstate effort and understate elapsed time. | F14: BKKB
A15: I12 | B15: Participant | C15: Model note | D15: Start event refers to the heir; in disability cases the applicant may be the employee. | E15: Wording of trigger and applicant role. | F15: Model owner

Sheet Assumptions & Legend
A1: Assumptions and legend
A3: Working hours per day | B3: 8 | C3: Assumption. Used to convert stated 'day' times to hours and hours to working days. Edit to test sensitivity.
A4: Citizen visit counts are minimums inferred from the model (blue). Cost to citizen is not stated in the source.
A5: Legend
A6: Blue text | C6: Hard-coded input from the source (stated times) or a counted value.
A7: Black text | C7: Formula.
A8: Yellow fill | C8: Assumption you can edit.
A9: Orange row (process map) | C9: Inferred step: not in the source map; derived from the service profile, document list or terms of service.
A10: Red row (process map) | C10: Defect return and rework exception path.
A11: Blue row (process map) | C11: Recurring monthly disbursement (up to 15 years).
A12: 'Immediate' | C12: Recorded as 0 hours.
A13: 'Not stated' | C13: Left blank; excluded from totals. Totals therefore understate elapsed time.
A14: Phase P0, R, I | C14: Excluded from the stated-time total: P0 and I have no stated times; R is an exception path.
A15: Source | C15: BKKB_Monthly_Welfare_Grant_AsIs.bpmn, which references the BKKB step table, source process map, service profile and comparison table.
